'Traceback (most recent call last):
  File "C:\\Program Files\\JetBrains\\PyCharm 2018.2.1\\helpers\\pydev\\_pydevd_bundle\\pydevd_resolver.py", line 166, in _getPyDictionary
    attr = getattr(var, n)
AttributeError: text
'